<!-- Author: Jacob Meredith (jmer@udel.edu)-->
<?xml version="1.0" ?>
<mujoco>
    <option timestep="0.005" />
    <worldbody>
        <body name="box" pos="0 0 10">
            <geom mass="1" size="0.15 0.15 0.15" type="box"/>
            <joint name='box_z' type='slide' axis='0 0 1' limited='false' damping='.01'/>
	    <joint name='box_y' type='slide' axis='0 1 0' limited='false' damping='.01'/>
	    <joint name='box_x' type='hinge' axis='1 0 0' limited='false' damping='.01'/>
        </body>
        
        <body name="floor" pos="0 0 0.025">
            <geom condim="3" size="5.0 5.0 0.02" rgba="0 1 0 1" type="box"/>
        </body>
    </worldbody>
</mujoco>
